<?xml version="1.0" encoding="utf-8"?>
<robot name="robot_display">
  <link name="body"/>

  <joint name="body_to_base_footprint_joint" type="fixed">
    <parent link="body" />
    <child link="base_footprint" />
    <origin xyz="-0.0139987 -0.0233413 -0.8458771" rpy="0 0 0" />
  </joint>

  <link name="base_footprint"/>
  
  <link name="base_link">
    <inertial>
      <origin xyz="-0.0098325143429585 -5.2540282666803E-05 0.392384583771952" rpy="0 0 0" />
      <mass value="1.52093247375048" />
      <inertia
        ixx="0.0176542350747674"
        ixy="-3.064862511353E-08"
        ixz="2.89095999810399E-05"
        iyy="0.0170775483739283"
        iyz="-6.04177568974473E-08"
        izz="0.00135407024623668" />
    </inertial>
    <visual>
      <origin xyz="0 0 0" rpy="0 0 0" />
      <geometry>
        <mesh filename="package://robot_display/meshes/base_link.STL" />
      </geometry>
      <material name="">
        <color rgba="1.0 1.0 1.0 1" />
      </material>
    </visual>
    <collision>
      <origin xyz="0 0 0" rpy="0 0 0" />
      <geometry>
        <mesh filename="package://robot_display/meshes/base_link.STL" />
      </geometry>
    </collision>
  </link>

  <joint name="base_footprint_joint" type="fixed">
    <parent link="base_footprint"/>
    <child link="base_link"/>
    <origin xyz="0 0 0.0105" rpy="0 0 0"/>
  </joint>

  <link name="whell_left_link">
    <inertial>
      <origin xyz="-7.85437210621548E-07 0.00048137342557214 1.11756020021447E-06" rpy="0 0 0" />
      <mass value="0.315479735385035" />
      <inertia
        ixx="0.000221117820208823"
        ixy="3.5833843868722E-10"
        ixz="-6.72123977051372E-09"
        iyy="0.000357084383299597"
        iyz="1.4251993170265E-08"
        izz="0.000221134649609164" />
    </inertial>
    <visual>
      <origin xyz="0 0 0" rpy="0 0 0" />
      <geometry>
        <mesh filename="package://robot_display/meshes/whell_left_link.STL" />
      </geometry>
      <material name="">
        <color rgba="0.2 1 0.2 1" />
      </material>
    </visual>
    <collision>
      <origin xyz="0 0 0" rpy="0 0 0" />
      <geometry>
        <mesh filename="package://robot_display/meshes/whell_left_link.STL" />
      </geometry>
    </collision>
  </link>

  <joint name="whell_left_joint" type="continuous">
    <origin xyz="0 0.188 0.04" rpy="0 0 0" />
    <parent link="base_link" />
    <child link="whell_left_link" />
    <axis xyz="0 1 0" />
  </joint>

  <link name="wheel_right_link">
    <inertial>
      <origin xyz="7.85441963985917E-07 -0.000481373418943581 1.11756507803484E-06" rpy="0 0 0" />
      <mass value="0.315479735504946" />
      <inertia
        ixx="0.000221117820259764"
        ixy="3.58314078627961E-10"
        ixz="6.72121924957937E-09"
        iyy="0.000357084383339721"
        iyz="-1.42520181537281E-08"
        izz="0.000221134649658052" />
    </inertial>
    <visual>
      <origin xyz="0 0 0" rpy="0 0 0" />
      <geometry>
        <mesh filename="package://robot_display/meshes/wheel_right_link.STL" />
      </geometry>
      <material name="">
        <color rgba="0.2 1 0.2 1" />
      </material>
    </visual>
    <collision>
      <origin xyz="0 0 0" rpy="0 0 0" />
      <geometry>
        <mesh filename="package://robot_display/meshes/wheel_right_link.STL" />
      </geometry>
    </collision>
  </link>

  <joint name="wheel_right_joint" type="continuous">
    <origin xyz="0 -0.188 0.04" rpy="0 0 0" />
    <parent link="base_link" />
    <child link="wheel_right_link" />
    <axis xyz="0 1 0" />
  </joint>

  <link name="screw_link">
    <inertial>
      <origin
        xyz="-0.00427100433072362 3.13763129416249E-05 0.047332346870503"
        rpy="0 0 0" />
      <mass
        value="0.510258972883763" />
      <inertia
        ixx="0.00329335052583588"
        ixy="2.96626302923215E-07"
        ixz="-2.59064528728889E-06"
        iyy="0.00083633633896411"
        iyz="8.71877566364901E-08"
        izz="0.00268588094530677" />
    </inertial>    
    <visual>
      <origin xyz="0 0 0" rpy="0 0 0" />
      <geometry>
        <mesh filename="package://robot_display/meshes/screw_link.STL" />
      </geometry>
      <material name="">
        <color rgba="1 0.5 0 1" />
      </material>
    </visual>
    <collision>
      <origin xyz="0 0 0" rpy="0 0 0" />
      <geometry>
        <mesh filename="package://robot_display/meshes/screw_link.STL" />
      </geometry>
    </collision>
  </link>

  <joint name="screw_joint" type="prismatic">
    <origin xyz="0.0616483321125747 5.00000000000496E-05 0.671" rpy="0 0 0" />
    <parent link="base_link" />
    <child link="screw_link" />
    <axis xyz="0 0 -1" />
    <limit lower="-0.2" upper="0" effort="100" velocity="0.1" />
  </joint>

  <link name="livox_poo_link">
    <inertial>
      <origin xyz="-0.0011535215104774 -1.68497683204461E-05 0.0041860206540324" rpy="0 0 0" />
      <mass value="0.0525930263369941" />
      <inertia
        ixx="1.13651947226529E-05"
        ixy="-5.6033368334055E-09"
        ixz="4.23764794898073E-10"
        iyy="1.13970227331633E-05"
        iyz="-6.00563014356558E-10"
        izz="1.91794026196399E-05" />
      </inertial>
    <visual>
      <origin xyz="0 0 0" rpy="0 0 0" />
      <geometry>
        <mesh filename="package://robot_display/meshes/livox_link.STL" />
      </geometry>
      <material name="">
        <color rgba="0 0.2 0.8 1" />
      </material>
    </visual>
    <collision>
      <origin xyz="0 0 0" rpy="0 0 0" />
      <geometry>
        <mesh filename="package://robot_display/meshes/livox_link.STL" />
      </geometry>
    </collision>
  </link>

  <joint name="livox_joint" type="fixed">
    <origin
      xyz="0.00299873713924339 5.12624561495789E-05 0.858417099999998"
      rpy="0 0 0" />
    <parent link="base_link" />
    <child link="livox_poo_link" />
  </joint>

  <link name="livox_frame"/>
  <joint name="livox_poo_to_livox_joint" type="fixed">
    <parent link="livox_poo_link" />
    <child link="livox_frame" />
    <origin xyz="0 0 0.02108" rpy="0 0 0" />
  </joint>
  
  <link name="imu_link"/>
  <joint name="livox_frame_to_livox_body_joint" type="fixed">
    <parent link="livox_frame" />
    <child link="imu_link" />
    <origin xyz="0.011 0.02329 -0.04412" rpy="0 0 0" />
  </joint>
</robot>